<?xml version="1.0" ?>
<!-- =================================================================================== -->
<!-- |    This document was autogenerated by xacro from /home/meka/mekabot/meka-ros-pkg/meka_description/robots/simc.urdf.xacro | -->
<!-- |    EDITING THIS FILE BY HAND IS NOT RECOMMENDED                                 | -->
<!-- =================================================================================== -->
<robot name="meka" xmlns:controller="http://playerstage.sourceforge.net/gazebo/xmlschema/#controller" xmlns:interface="http://playerstage.sourceforge.net/gazebo/xmlschema/#interface" xmlns:sensor="http://playerstage.sourceforge.net/gazebo/xmlschema/#sensor" xmlns:xacro="http://playerstage.sourceforge.net/gazebo/xmlschema/#interface">
  <!-- generic simulator_gazebo plugins for starting mechanism control, ros time, ros battery -->
  <gazebo>
    <controller:gazebo_ros_controller_manager name="gazebo_ros_controller_manager" plugin="libgazebo_ros_controller_manager.so">
      <alwaysOn>true</alwaysOn>
      <updateRate>10000.0</updateRate>
    </controller:gazebo_ros_controller_manager>
  </gazebo>
  <!--<include filename="$(find meka_description)/transmissions/uta.transmission.xacro" />-->
  <!-- Meka Base -->
  <!-- Meka Zlift -->
  <!-- Meka Arm -->
  <!-- Meka Hand -->
  <!-- Meka Head -->
  <!-- john added transmissions -->
  <!--<include filename="$(find meka_description)/transmissions/H2R2_r_hand_defs.transmission.xacro" />-->
  <!--<include filename="$(find meka_description)/transmissions/S2R1_head_defs.transmission.xacro" />-->
  <material name="GreyA">
    <!-- darkest -->
    <color rgba="0.3 0.3 0.3 1.0"/>
  </material>
  <material name="GreyB">
    <color rgba="0.5 0.5 0.5 1.0"/>
  </material>
  <material name="GreyC">
    <color rgba="0.7 0.7 0.7 1.0"/>
  </material>
  <!-- john added transmissions -->
  <transmission name="right_arm_t0" type="pr2_mechanism_model/SimpleTransmission">
    <actuator name="right_arm_a0"/>
    <joint name="right_arm_j0"/>
    <mechanicalReduction>1</mechanicalReduction>
  </transmission>
  <transmission name="right_arm_t1" type="pr2_mechanism_model/SimpleTransmission">
    <actuator name="right_arm_a1"/>
    <joint name="right_arm_j1"/>
    <mechanicalReduction>1</mechanicalReduction>
  </transmission>
  <transmission name="right_arm_t2" type="pr2_mechanism_model/SimpleTransmission">
    <actuator name="right_arm_a2"/>
    <joint name="right_arm_j2"/>
    <mechanicalReduction>1</mechanicalReduction>
  </transmission>
  <transmission name="right_arm_t3" type="pr2_mechanism_model/SimpleTransmission">
    <actuator name="right_arm_a3"/>
    <joint name="right_arm_j3"/>
    <mechanicalReduction>1</mechanicalReduction>
  </transmission>
  <transmission name="right_arm_t4" type="pr2_mechanism_model/SimpleTransmission">
    <actuator name="right_arm_a4"/>
    <joint name="right_arm_j4"/>
    <mechanicalReduction>1</mechanicalReduction>
  </transmission>
  <transmission name="right_arm_t5" type="pr2_mechanism_model/SimpleTransmission">
    <actuator name="right_arm_a5"/>
    <joint name="right_arm_j5"/>
    <mechanicalReduction>1</mechanicalReduction>
  </transmission>
  <transmission name="right_arm_t6" type="pr2_mechanism_model/SimpleTransmission">
    <actuator name="right_arm_a6"/>
    <joint name="right_arm_j6"/>
    <mechanicalReduction>1</mechanicalReduction>
  </transmission>
  <m3_r_hand_transmission/>
  <joint name="palm_joint" type="fixed">
    <origin rpy="0 0 0" xyz="0 0 -0.04414"/>
    <parent link="handmount_RIGHT"/>
    <child link="palm"/>
  </joint>
  <link name="palm">
    <inertial>
      <mass value="0.663"/>
      <origin xyz="0.001459 0.001619 -0.051312"/>
      <inertia ixx="0.000873" ixy="0.000031" ixz="-0.000008" iyy="0.000597" iyz="0.000016" izz="0.000565"/>
    </inertial>
    <visual>
      <material name="GreyA"/>
      <origin rpy="0 0 0 " xyz="0 0 0"/>
      <geometry name="palm_geom">
        <mesh filename="package://meka_description/meshes/mid_res/H2R3/H2R3_RT8_palm_right.dae"/>
      </geometry>
    </visual>
    <collision>
      <origin rpy="0.0 0.0 0.0 " xyz="0 0 0"/>
      <geometry name="palm_collision">
        <mesh filename="package://meka_description/meshes/low_res/H2R3/H2R3_RT8_palm_right.stl"/>
      </geometry>
    </collision>
  </link>
  <joint name="right_hand_j0" type="revolute">
    <axis xyz="0 0 -1"/>
    <origin rpy="0 0 0" xyz="-0.02 0.028 -0.03"/>
    <parent link="palm"/>
    <child link="thumb0"/>
    <limit effort="100" lower="-0.698131700798" upper="0.261799387799" velocity="0.349065850399"/>
  </joint>
  <link name="thumb0">
    <inertial>
      <mass value="0.0117"/>
      <origin xyz="0.0 0.0 0.0"/>
      <inertia ixx="0.0" ixy="0.0" ixz="0.0" iyy="0.0" iyz="0.0" izz="0.0"/>
    </inertial>
    <visual>
      <material name="GreyA"/>
      <origin rpy="0 0 0 " xyz="0 0 0"/>
      <geometry name="thumb0_geom">
        <mesh filename="package://meka_description/meshes/mid_res/H2R3/H2R3_RJ0_thumb_abductlink.dae"/>
      </geometry>
    </visual>
    <collision>
      <origin rpy="0.0 0.0 0.0 " xyz="0 0 0"/>
      <geometry name="thumb0_collision">
        <mesh filename="package://meka_description/meshes/low_res/H2R3/H2R3_RJ0_thumb_abductlink.stl"/>
      </geometry>
    </collision>
  </link>
  <joint name="right_hand_j1" type="revolute">
    <axis xyz="0 -1 0"/>
    <limit effort="100" lower="-1.41230297742" upper="1.41214589779" velocity="1.308996939"/>
    <origin rpy="0 0 0" xyz="-0.018 0 0"/>
    <parent link="thumb0"/>
    <child link="thumb1"/>
  </joint>
  <link name="thumb1">
    <inertial>
      <mass value="0.0344"/>
      <origin xyz="0.0 0.0 0.0"/>
      <inertia ixx="0.0" ixy="0.0" ixz="0.0" iyy="0.0" iyz="0.0" izz="0.0"/>
    </inertial>
    <visual>
      <material name="GreyB"/>
      <origin rpy="0 0 0 " xyz="0 0 0"/>
      <geometry name="thumb1_geom">
        <mesh filename="package://meka_description/meshes/mid_res/H2R3/H2R3_thumb_knuckle1.dae"/>
      </geometry>
    </visual>
    <collision>
      <origin rpy="0.0 0.0 0.0 " xyz="0 0 0"/>
      <geometry name="thumb1_collision">
        <mesh filename="package://meka_description/meshes/low_res/H2R3/H2R3_thumb_knuckle1.stl"/>
      </geometry>
    </collision>
  </link>
  <joint name="right_hand_j2" type="revolute">
    <axis xyz="0 -1 0"/>
    <origin rpy="0 0 0" xyz="-0.044 0 0"/>
    <parent link="thumb1"/>
    <child link="thumb2"/>
    <limit effort="100" lower="-0.260752190248" upper="0.260752190248" velocity="0.872664625997"/>
  </joint>
  <link name="thumb2">
    <inertial>
      <mass value="0.01"/>
      <origin xyz="0.0 0.0 0.0"/>
      <inertia ixx="0.0" ixy="0.0" ixz="0.0" iyy="0.0" iyz="0.0" izz="0.0"/>
    </inertial>
    <visual>
      <material name="GreyC"/>
      <origin rpy="0 0 0 " xyz="0 0 0"/>
      <geometry name="thumb_knuckle2_geom">
        <mesh filename="package://meka_description/meshes/mid_res/H2R3/H2R3_thumb_knuckle2.dae"/>
      </geometry>
    </visual>
    <collision>
      <origin rpy="0.0 0.0 0.0 " xyz="0 0 0"/>
      <geometry name="thumb_knuckle2_collision">
        <mesh filename="package://meka_description/meshes/low_res/H2R3/H2R3_thumb_knuckle2.stl"/>
      </geometry>
    </collision>
  </link>
  <joint name="right_hand_j3" type="revolute">
    <axis xyz="0 1 0"/>
    <origin rpy="0 0 0" xyz="0 0.028 -0.101"/>
    <parent link="palm"/>
    <child link="index0"/>
    <limit effort="100" lower="-0.123429684701" upper="0.647028460299" velocity="0.872664625997"/>
  </joint>
  <link name="index0">
    <inertial>
      <mass value="0.01"/>
      <origin xyz="0.0 0.0 0.0"/>
      <inertia ixx="0.0" ixy="0.0" ixz="0.0" iyy="0.0" iyz="0.0" izz="0.0"/>
    </inertial>
    <visual>
      <material name="GreyA"/>
      <origin rpy="0 0 0 " xyz="0 0 0"/>
      <geometry name="index0_geom">
        <mesh filename="package://meka_description/meshes/mid_res/H2R3/H2R3_finger_knuckle1.dae"/>
      </geometry>
    </visual>
    <collision>
      <origin rpy="0.0 0.0 0.0 " xyz="0 0 0"/>
      <geometry name="index0__collision">
        <mesh filename="package://meka_description/meshes/low_res/H2R3/H2R3_finger_knuckle1.stl"/>
      </geometry>
    </collision>
  </link>
  <joint name="right_hand_j4" type="revolute">
    <axis xyz="0 1 0"/>
    <limit effort="100" lower="-0.610690705273" upper="0.610690705273" velocity="27.9252680319"/>
    <origin rpy="0 0 0" xyz="0 0 -0.044"/>
    <parent link="index0"/>
    <child link="index1"/>
  </joint>
  <link name="index1">
    <inertial>
      <mass value="0.0429"/>
      <origin xyz="0.0 0.0 0.0"/>
      <inertia ixx="0.0" ixy="0.0" ixz="0.0" iyy="0.0" iyz="0.0" izz="0.0"/>
    </inertial>
    <visual>
      <material name="GreyC"/>
      <origin rpy="0 0 0 " xyz="0 0 0"/>
      <geometry name="index1_geom">
        <mesh filename="package://meka_description/meshes/mid_res/H2R3/H2R3_finger_knuckle2.dae"/>
      </geometry>
    </visual>
    <collision>
      <origin rpy="0.0 0.0 0.0 " xyz="0 0 0"/>
      <geometry name="index1_collision">
        <mesh filename="package://meka_description/meshes/low_res/H2R3/H2R3_finger_knuckle2.stl"/>
      </geometry>
    </collision>
  </link>
  <joint name="right_hand_j5" type="revolute">
    <axis xyz="0 1 0"/>
    <limit effort="100" lower="-0.597077137107" upper="0.597129496985" velocity="27.9252680319"/>
    <origin rpy="0 0 0" xyz="0 0 -0.032"/>
    <parent link="index1"/>
    <child link="index2"/>
  </joint>
  <link name="index2">
    <inertial>
      <mass value="0.01"/>
      <origin xyz="0.0 0.0 0.0"/>
      <inertia ixx="0.0" ixy="0.0" ixz="0.0" iyy="0.0" iyz="0.0" izz="0.0"/>
    </inertial>
    <visual>
      <material name="GreyC"/>
      <origin rpy="0 0 0 " xyz="0 0 0"/>
      <geometry name="index2_geom">
        <mesh filename="package://meka_description/meshes/mid_res/H2R3/H2R3_finger_knuckle3.dae"/>
      </geometry>
    </visual>
    <collision>
      <origin rpy="0.0 0.0 0.0 " xyz="0 0 0"/>
      <geometry name="index2_collision">
        <mesh filename="package://meka_description/meshes/low_res/H2R3/H2R3_finger_knuckle3.stl"/>
      </geometry>
    </collision>
  </link>
  <joint name="right_hand_j6" type="revolute">
    <axis xyz="0 1 0"/>
    <origin rpy="0 0 0" xyz="0 0 -0.101"/>
    <parent link="palm"/>
    <child link="ring0"/>
    <limit effort="100" lower="-0.123429684701" upper="0.647028460299" velocity="0.872664625997"/>
  </joint>
  <link name="ring0">
    <inertial>
      <mass value="0.01"/>
      <origin xyz="0.0 0.0 0.0"/>
      <inertia ixx="0.0" ixy="0.0" ixz="0.0" iyy="0.0" iyz="0.0" izz="0.0"/>
    </inertial>
    <visual>
      <material name="GreyA"/>
      <origin rpy="0 0 0 " xyz="0 0 0"/>
      <geometry name="ring0_geom">
        <mesh filename="package://meka_description/meshes/mid_res/H2R3/H2R3_finger_knuckle1.dae"/>
      </geometry>
    </visual>
    <collision>
      <origin rpy="0.0 0.0 0.0 " xyz="0 0 0"/>
      <geometry name="ring0__collision">
        <mesh filename="package://meka_description/meshes/low_res/H2R3/H2R3_finger_knuckle1.stl"/>
      </geometry>
    </collision>
  </link>
  <joint name="right_hand_j7" type="revolute">
    <axis xyz="0 1 0"/>
    <limit effort="100" lower="-0.610690705273" upper="0.610690705273" velocity="27.9252680319"/>
    <origin rpy="0 0 0" xyz="0 0 -0.044"/>
    <parent link="ring0"/>
    <child link="ring1"/>
  </joint>
  <link name="ring1">
    <inertial>
      <mass value="0.0429"/>
      <origin xyz="0.0 0.0 0.0"/>
      <inertia ixx="0.0" ixy="0.0" ixz="0.0" iyy="0.0" iyz="0.0" izz="0.0"/>
    </inertial>
    <visual>
      <material name="GreyC"/>
      <origin rpy="0 0 0 " xyz="0 0 0"/>
      <geometry name="ring1_geom">
        <mesh filename="package://meka_description/meshes/mid_res/H2R3/H2R3_finger_knuckle2.dae"/>
      </geometry>
    </visual>
    <collision>
      <origin rpy="0.0 0.0 0.0 " xyz="0 0 0"/>
      <geometry name="ring1_collision">
        <mesh filename="package://meka_description/meshes/low_res/H2R3/H2R3_finger_knuckle2.stl"/>
      </geometry>
    </collision>
  </link>
  <joint name="right_hand_j8" type="revolute">
    <axis xyz="0 1 0"/>
    <limit effort="100" lower="-0.597077137107" upper="0.597129496985" velocity="27.9252680319"/>
    <origin rpy="0 0 0" xyz="0 0 -0.032"/>
    <parent link="ring1"/>
    <child link="ring2"/>
  </joint>
  <link name="ring2">
    <inertial>
      <mass value="0.01"/>
      <origin xyz="0.0 0.0 0.0"/>
      <inertia ixx="0.0" ixy="0.0" ixz="0.0" iyy="0.0" iyz="0.0" izz="0.0"/>
    </inertial>
    <visual>
      <material name="GreyC"/>
      <origin rpy="0 0 0 " xyz="0 0 0"/>
      <geometry name="ring2_geom">
        <mesh filename="package://meka_description/meshes/mid_res/H2R3/H2R3_finger_knuckle3.dae"/>
      </geometry>
    </visual>
    <collision>
      <origin rpy="0.0 0.0 0.0 " xyz="0 0 0"/>
      <geometry name="ring2_collision">
        <mesh filename="package://meka_description/meshes/low_res/H2R3/H2R3_finger_knuckle3.stl"/>
      </geometry>
    </collision>
  </link>
  <joint name="right_hand_j9" type="revolute">
    <axis xyz="0 1 0"/>
    <origin rpy="0 0 0" xyz="0 -0.028 -0.101"/>
    <parent link="palm"/>
    <child link="pinky0"/>
    <limit effort="100" lower="-0.123429684701" upper="0.647028460299" velocity="0.872664625997"/>
  </joint>
  <link name="pinky0">
    <inertial>
      <mass value="0.01"/>
      <origin xyz="0.0 0.0 0.0"/>
      <inertia ixx="0.0" ixy="0.0" ixz="0.0" iyy="0.0" iyz="0.0" izz="0.0"/>
    </inertial>
    <visual>
      <material name="GreyA"/>
      <origin rpy="0 0 0 " xyz="0 0 0"/>
      <geometry name="pinky0_geom">
        <mesh filename="package://meka_description/meshes/mid_res/H2R3/H2R3_finger_knuckle1.dae"/>
      </geometry>
    </visual>
    <collision>
      <origin rpy="0.0 0.0 0.0 " xyz="0 0 0"/>
      <geometry name="pinky0__collision">
        <mesh filename="package://meka_description/meshes/low_res/H2R3/H2R3_finger_knuckle1.stl"/>
      </geometry>
    </collision>
  </link>
  <joint name="right_hand_j10" type="revolute">
    <axis xyz="0 1 0"/>
    <limit effort="100" lower="-0.610690705273" upper="0.610690705273" velocity="27.9252680319"/>
    <origin rpy="0 0 0" xyz="0 0 -0.044"/>
    <parent link="pinky0"/>
    <child link="pinky1"/>
  </joint>
  <link name="pinky1">
    <inertial>
      <mass value="0.0429"/>
      <origin xyz="0.0 0.0 0.0"/>
      <inertia ixx="0.0" ixy="0.0" ixz="0.0" iyy="0.0" iyz="0.0" izz="0.0"/>
    </inertial>
    <visual>
      <material name="GreyC"/>
      <origin rpy="0 0 0 " xyz="0 0 0"/>
      <geometry name="pinky1_geom">
        <mesh filename="package://meka_description/meshes/mid_res/H2R3/H2R3_finger_knuckle2.dae"/>
      </geometry>
    </visual>
    <collision>
      <origin rpy="0.0 0.0 0.0 " xyz="0 0 0"/>
      <geometry name="pinky1_collision">
        <mesh filename="package://meka_description/meshes/low_res/H2R3/H2R3_finger_knuckle2.stl"/>
      </geometry>
    </collision>
  </link>
  <joint name="right_hand_j11" type="revolute">
    <axis xyz="0 1 0"/>
    <limit effort="100" lower="-0.597077137107" upper="0.597129496985" velocity="27.9252680319"/>
    <origin rpy="0 0 0" xyz="0 0 -0.032"/>
    <parent link="pinky1"/>
    <child link="pinky2"/>
  </joint>
  <link name="pinky2">
    <inertial>
      <mass value="0.01"/>
      <origin xyz="0.0 0.0 0.0"/>
      <inertia ixx="0.0" ixy="0.0" ixz="0.0" iyy="0.0" iyz="0.0" izz="0.0"/>
    </inertial>
    <visual>
      <material name="GreyC"/>
      <origin rpy="0 0 0 " xyz="0 0 0"/>
      <geometry name="pinky2_geom">
        <mesh filename="package://meka_description/meshes/mid_res/H2R3/H2R3_finger_knuckle3.dae"/>
      </geometry>
    </visual>
    <collision>
      <origin rpy="0.0 0.0 0.0 " xyz="0 0 0"/>
      <geometry name="pinky2_collision">
        <mesh filename="package://meka_description/meshes/low_res/H2R3/H2R3_finger_knuckle3.stl"/>
      </geometry>
    </collision>
  </link>
  <joint name="l_palm_joint" type="fixed">
    <origin rpy="0 0 0" xyz="0 0 -0.04414"/>
    <parent link="handmount_LEFT"/>
    <child link="l_palm"/>
  </joint>
  <link name="l_palm">
    <inertial>
      <mass value="0.663"/>
      <origin xyz="0.001459 0.001619 -0.051312"/>
      <inertia ixx="0.000873" ixy="0.000031" ixz="-0.000008" iyy="0.000597" iyz="0.000016" izz="0.000565"/>
    </inertial>
    <visual>
      <material name="GreyA"/>
      <origin rpy="0 0 0 " xyz="0 0 0"/>
      <geometry name="l_palm_geom">
        <mesh filename="package://meka_description/meshes/mid_res/H2R3/H2R3_LT8_palm_left.dae"/>
      </geometry>
    </visual>
    <collision>
      <origin rpy="0.0 0.0 0.0 " xyz="0 0 0"/>
      <geometry name="l_palm_collision">
        <mesh filename="package://meka_description/meshes/low_res/H2R3/H2R3_RT8_palm_right.stl"/>
      </geometry>
    </collision>
  </link>
  <joint name="left_hand_j0" type="revolute">
    <axis xyz="0 0 -1"/>
    <origin rpy="0 0 0" xyz="-0.02 -0.028 -0.03"/>
    <parent link="l_palm"/>
    <child link="l_thumb0"/>
    <limit effort="100" lower="-0.698131700798" upper="0.261799387799" velocity="0.349065850399"/>
  </joint>
  <link name="l_thumb0">
    <inertial>
      <mass value="0.0117"/>
      <origin xyz="0.0 0.0 0.0"/>
      <inertia ixx="0.0" ixy="0.0" ixz="0.0" iyy="0.0" iyz="0.0" izz="0.0"/>
    </inertial>
    <visual>
      <material name="GreyA"/>
      <origin rpy="0 0 0 " xyz="0 0 0"/>
      <geometry name="l_thumb0_geom">
        <mesh filename="package://meka_description/meshes/mid_res/H2R3/H2R3_RJ0_thumb_abductlink.dae"/>
      </geometry>
    </visual>
    <collision>
      <origin rpy="0.0 0.0 0.0 " xyz="0 0 0"/>
      <geometry name="l_thumb0_collision">
        <mesh filename="package://meka_description/meshes/low_res/H2R3/H2R3_RJ0_thumb_abductlink.stl"/>
      </geometry>
    </collision>
  </link>
  <joint name="left_hand_j1" type="revolute">
    <axis xyz="0 -1 0"/>
    <limit effort="100" lower="-1.41230297742" upper="1.41214589779" velocity="1.308996939"/>
    <origin rpy="0 0 0" xyz="-0.018 0 0"/>
    <parent link="l_thumb0"/>
    <child link="l_thumb1"/>
  </joint>
  <link name="l_thumb1">
    <inertial>
      <mass value="0.0344"/>
      <origin xyz="0.0 0.0 0.0"/>
      <inertia ixx="0.0" ixy="0.0" ixz="0.0" iyy="0.0" iyz="0.0" izz="0.0"/>
    </inertial>
    <visual>
      <material name="GreyB"/>
      <origin rpy="0 0 0 " xyz="0 0 0"/>
      <geometry name="l_thumb1_geom">
        <mesh filename="package://meka_description/meshes/mid_res/H2R3/H2R3_thumb_knuckle1.dae"/>
      </geometry>
    </visual>
    <collision>
      <origin rpy="0.0 0.0 0.0 " xyz="0 0 0"/>
      <geometry name="l_thumb1_collision">
        <mesh filename="package://meka_description/meshes/low_res/H2R3/H2R3_thumb_knuckle1.stl"/>
      </geometry>
    </collision>
  </link>
  <joint name="left_hand_j2" type="revolute">
    <axis xyz="0 -1 0"/>
    <origin rpy="0 0 0" xyz="-0.044 0 0"/>
    <parent link="l_thumb1"/>
    <child link="l_thumb2"/>
    <limit effort="100" lower="-0.260752190248" upper="0.260752190248" velocity="0.872664625997"/>
  </joint>
  <link name="l_thumb2">
    <inertial>
      <mass value="0.01"/>
      <origin xyz="0.0 0.0 0.0"/>
      <inertia ixx="0.0" ixy="0.0" ixz="0.0" iyy="0.0" iyz="0.0" izz="0.0"/>
    </inertial>
    <visual>
      <material name="GreyC"/>
      <origin rpy="0 0 0 " xyz="0 0 0"/>
      <geometry name="l_thumb_knuckle2_geom">
        <mesh filename="package://meka_description/meshes/mid_res/H2R3/H2R3_thumb_knuckle2.dae"/>
      </geometry>
    </visual>
    <collision>
      <origin rpy="0.0 0.0 0.0 " xyz="0 0 0"/>
      <geometry name="l_thumb_knuckle2_collision">
        <mesh filename="package://meka_description/meshes/low_res/H2R3/H2R3_thumb_knuckle2.stl"/>
      </geometry>
    </collision>
  </link>
  <joint name="left_hand_j3" type="revolute">
    <axis xyz="0 1 0"/>
    <origin rpy="0 0 0" xyz="0 0.028 -0.101"/>
    <parent link="l_palm"/>
    <child link="l_index0"/>
    <limit effort="100" lower="-0.123429684701" upper="0.647028460299" velocity="0.872664625997"/>
  </joint>
  <link name="l_index0">
    <inertial>
      <mass value="0.01"/>
      <origin xyz="0.0 0.0 0.0"/>
      <inertia ixx="0.0" ixy="0.0" ixz="0.0" iyy="0.0" iyz="0.0" izz="0.0"/>
    </inertial>
    <visual>
      <material name="GreyA"/>
      <origin rpy="0 0 0 " xyz="0 0 0"/>
      <geometry name="l_index0_geom">
        <mesh filename="package://meka_description/meshes/mid_res/H2R3/H2R3_finger_knuckle1.dae"/>
      </geometry>
    </visual>
    <collision>
      <origin rpy="0.0 0.0 0.0 " xyz="0 0 0"/>
      <geometry name="l_index0__collision">
        <mesh filename="package://meka_description/meshes/low_res/H2R3/H2R3_finger_knuckle1.stl"/>
      </geometry>
    </collision>
  </link>
  <joint name="left_hand_j4" type="revolute">
    <axis xyz="0 1 0"/>
    <limit effort="100" lower="-0.610690705273" upper="0.610690705273" velocity="27.9252680319"/>
    <origin rpy="0 0 0" xyz="0 0 -0.044"/>
    <parent link="l_index0"/>
    <child link="l_index1"/>
  </joint>
  <link name="l_index1">
    <inertial>
      <mass value="0.0429"/>
      <origin xyz="0.0 0.0 0.0"/>
      <inertia ixx="0.0" ixy="0.0" ixz="0.0" iyy="0.0" iyz="0.0" izz="0.0"/>
    </inertial>
    <visual>
      <material name="GreyC"/>
      <origin rpy="0 0 0 " xyz="0 0 0"/>
      <geometry name="l_index1_geom">
        <mesh filename="package://meka_description/meshes/mid_res/H2R3/H2R3_finger_knuckle2.dae"/>
      </geometry>
    </visual>
    <collision>
      <origin rpy="0.0 0.0 0.0 " xyz="0 0 0"/>
      <geometry name="l_index1_collision">
        <mesh filename="package://meka_description/meshes/low_res/H2R3/H2R3_finger_knuckle2.stl"/>
      </geometry>
    </collision>
  </link>
  <joint name="left_hand_j5" type="revolute">
    <axis xyz="0 1 0"/>
    <limit effort="100" lower="-0.597077137107" upper="0.597129496985" velocity="27.9252680319"/>
    <origin rpy="0 0 0" xyz="0 0 -0.032"/>
    <parent link="l_index1"/>
    <child link="l_index2"/>
  </joint>
  <link name="l_index2">
    <inertial>
      <mass value="0.01"/>
      <origin xyz="0.0 0.0 0.0"/>
      <inertia ixx="0.0" ixy="0.0" ixz="0.0" iyy="0.0" iyz="0.0" izz="0.0"/>
    </inertial>
    <visual>
      <material name="GreyC"/>
      <origin rpy="0 0 0 " xyz="0 0 0"/>
      <geometry name="l_index2_geom">
        <mesh filename="package://meka_description/meshes/mid_res/H2R3/H2R3_finger_knuckle3.dae"/>
      </geometry>
    </visual>
    <collision>
      <origin rpy="0.0 0.0 0.0 " xyz="0 0 0"/>
      <geometry name="l_index2_collision">
        <mesh filename="package://meka_description/meshes/low_res/H2R3/H2R3_finger_knuckle3.stl"/>
      </geometry>
    </collision>
  </link>
  <joint name="left_hand_j6" type="revolute">
    <axis xyz="0 1 0"/>
    <origin rpy="0 0 0" xyz="0 0 -0.101"/>
    <parent link="l_palm"/>
    <child link="l_ring0"/>
    <limit effort="100" lower="-0.123429684701" upper="0.647028460299" velocity="0.872664625997"/>
  </joint>
  <link name="l_ring0">
    <inertial>
      <mass value="0.01"/>
      <origin xyz="0.0 0.0 0.0"/>
      <inertia ixx="0.0" ixy="0.0" ixz="0.0" iyy="0.0" iyz="0.0" izz="0.0"/>
    </inertial>
    <visual>
      <material name="GreyA"/>
      <origin rpy="0 0 0 " xyz="0 0 0"/>
      <geometry name="l_ring0_geom">
        <mesh filename="package://meka_description/meshes/mid_res/H2R3/H2R3_finger_knuckle1.dae"/>
      </geometry>
    </visual>
    <collision>
      <origin rpy="0.0 0.0 0.0 " xyz="0 0 0"/>
      <geometry name="l_ring0__collision">
        <mesh filename="package://meka_description/meshes/low_res/H2R3/H2R3_finger_knuckle1.stl"/>
      </geometry>
    </collision>
  </link>
  <joint name="left_hand_j7" type="revolute">
    <axis xyz="0 1 0"/>
    <limit effort="100" lower="-0.610690705273" upper="0.610690705273" velocity="27.9252680319"/>
    <origin rpy="0 0 0" xyz="0 0 -0.044"/>
    <parent link="l_ring0"/>
    <child link="l_ring1"/>
  </joint>
  <link name="l_ring1">
    <inertial>
      <mass value="0.0429"/>
      <origin xyz="0.0 0.0 0.0"/>
      <inertia ixx="0.0" ixy="0.0" ixz="0.0" iyy="0.0" iyz="0.0" izz="0.0"/>
    </inertial>
    <visual>
      <material name="GreyC"/>
      <origin rpy="0 0 0 " xyz="0 0 0"/>
      <geometry name="l_ring1_geom">
        <mesh filename="package://meka_description/meshes/mid_res/H2R3/H2R3_finger_knuckle2.dae"/>
      </geometry>
    </visual>
    <collision>
      <origin rpy="0.0 0.0 0.0 " xyz="0 0 0"/>
      <geometry name="l_ring1_collision">
        <mesh filename="package://meka_description/meshes/low_res/H2R3/H2R3_finger_knuckle2.stl"/>
      </geometry>
    </collision>
  </link>
  <joint name="left_hand_j8" type="revolute">
    <axis xyz="0 1 0"/>
    <limit effort="100" lower="-0.597077137107" upper="0.597129496985" velocity="27.9252680319"/>
    <origin rpy="0 0 0" xyz="0 0 -0.032"/>
    <parent link="l_ring1"/>
    <child link="l_ring2"/>
  </joint>
  <link name="l_ring2">
    <inertial>
      <mass value="0.01"/>
      <origin xyz="0.0 0.0 0.0"/>
      <inertia ixx="0.0" ixy="0.0" ixz="0.0" iyy="0.0" iyz="0.0" izz="0.0"/>
    </inertial>
    <visual>
      <material name="GreyC"/>
      <origin rpy="0 0 0 " xyz="0 0 0"/>
      <geometry name="l_ring2_geom">
        <mesh filename="package://meka_description/meshes/mid_res/H2R3/H2R3_finger_knuckle3.dae"/>
      </geometry>
    </visual>
    <collision>
      <origin rpy="0.0 0.0 0.0 " xyz="0 0 0"/>
      <geometry name="l_ring2_collision">
        <mesh filename="package://meka_description/meshes/low_res/H2R3/H2R3_finger_knuckle3.stl"/>
      </geometry>
    </collision>
  </link>
  <joint name="left_hand_j9" type="revolute">
    <axis xyz="0 1 0"/>
    <origin rpy="0 0 0" xyz="0 -0.028 -0.101"/>
    <parent link="l_palm"/>
    <child link="l_pinky0"/>
    <limit effort="100" lower="-0.123429684701" upper="0.647028460299" velocity="0.872664625997"/>
  </joint>
  <link name="l_pinky0">
    <inertial>
      <mass value="0.01"/>
      <origin xyz="0.0 0.0 0.0"/>
      <inertia ixx="0.0" ixy="0.0" ixz="0.0" iyy="0.0" iyz="0.0" izz="0.0"/>
    </inertial>
    <visual>
      <material name="GreyA"/>
      <origin rpy="0 0 0 " xyz="0 0 0"/>
      <geometry name="l_pinky0_geom">
        <mesh filename="package://meka_description/meshes/mid_res/H2R3/H2R3_finger_knuckle1.dae"/>
      </geometry>
    </visual>
    <collision>
      <origin rpy="0.0 0.0 0.0 " xyz="0 0 0"/>
      <geometry name="l_pinky0__collision">
        <mesh filename="package://meka_description/meshes/low_res/H2R3/H2R3_finger_knuckle1.stl"/>
      </geometry>
    </collision>
  </link>
  <joint name="left_hand_j10" type="revolute">
    <axis xyz="0 1 0"/>
    <limit effort="100" lower="-0.610690705273" upper="0.610690705273" velocity="27.9252680319"/>
    <origin rpy="0 0 0" xyz="0 0 -0.044"/>
    <parent link="l_pinky0"/>
    <child link="l_pinky1"/>
  </joint>
  <link name="l_pinky1">
    <inertial>
      <mass value="0.0429"/>
      <origin xyz="0.0 0.0 0.0"/>
      <inertia ixx="0.0" ixy="0.0" ixz="0.0" iyy="0.0" iyz="0.0" izz="0.0"/>
    </inertial>
    <visual>
      <material name="GreyC"/>
      <origin rpy="0 0 0 " xyz="0 0 0"/>
      <geometry name="l_pinky1_geom">
        <mesh filename="package://meka_description/meshes/mid_res/H2R3/H2R3_finger_knuckle2.dae"/>
      </geometry>
    </visual>
    <collision>
      <origin rpy="0.0 0.0 0.0 " xyz="0 0 0"/>
      <geometry name="l_pinky1_collision">
        <mesh filename="package://meka_description/meshes/low_res/H2R3/H2R3_finger_knuckle2.stl"/>
      </geometry>
    </collision>
  </link>
  <joint name="left_hand_j11" type="revolute">
    <axis xyz="0 1 0"/>
    <limit effort="100" lower="-0.597077137107" upper="0.597129496985" velocity="27.9252680319"/>
    <origin rpy="0 0 0" xyz="0 0 -0.032"/>
    <parent link="l_pinky1"/>
    <child link="l_pinky2"/>
  </joint>
  <link name="l_pinky2">
    <inertial>
      <mass value="0.01"/>
      <origin xyz="0.0 0.0 0.0"/>
      <inertia ixx="0.0" ixy="0.0" ixz="0.0" iyy="0.0" iyz="0.0" izz="0.0"/>
    </inertial>
    <visual>
      <material name="GreyC"/>
      <origin rpy="0 0 0 " xyz="0 0 0"/>
      <geometry name="l_pinky2_geom">
        <mesh filename="package://meka_description/meshes/mid_res/H2R3/H2R3_finger_knuckle3.dae"/>
      </geometry>
    </visual>
    <collision>
      <origin rpy="0.0 0.0 0.0 " xyz="0 0 0"/>
      <geometry name="l_pinky2_collision">
        <mesh filename="package://meka_description/meshes/low_res/H2R3/H2R3_finger_knuckle3.stl"/>
      </geometry>
    </collision>
  </link>
  <joint name="head_j0" type="revolute">
    <axis xyz="0 -1 0"/>
    <origin rpy="0 0 0" xyz="0.0 0.0 0.31155"/>
    <!-- transform from parent link to this joint frame -->
    <parent link="upper"/>
    <child link="neck_tilt"/>
    <limit effort="100" lower="-0.314159265359" upper="0.0174532925199" velocity="0.349065850399"/>
  </joint>
  <link name="neck_tilt">
    <inertial>
      <mass value="0.940"/>
      <origin xyz="0.000061 0.003310 0.028798"/>
      <inertia ixx="0.001395" ixy="-0.000000" ixz="-0.000000" iyy="0.001345" iyz="-0.000085" izz="0.000392"/>
    </inertial>
    <visual>
      <material name="GreyA"/>
      <origin rpy="0 0 0 " xyz="0 0 0"/>
      <geometry name="neck_tilt_geom">
        <mesh filename="package://meka_description/meshes/mid_res/S2R1/S2R1_SH1_neckTilt.dae"/>
      </geometry>
    </visual>
    <collision>
      <origin rpy="0.0 0.0 0.0 " xyz="0 0 0"/>
      <geometry name="neck_tilt_geom_collison">
        <mesh filename="package://meka_description/meshes/low_res/S2R1/S2R1_SH1_neckTilt.stl"/>
      </geometry>
    </collision>
  </link>
  <joint name="head_j1" type="revolute">
    <axis xyz="0 0 1"/>
    <limit effort="100" lower="-0.977384381117" upper="0.977384381117" velocity="1.308996939"/>
    <origin rpy="0 0 0" xyz="0 0 0.13849"/>
    <parent link="neck_tilt"/>
    <child link="neck_roll"/>
  </joint>
  <link name="neck_roll">
    <inertial>
      <mass value="0.409"/>
      <origin xyz="0.0 0.0 0.0"/>
      <inertia ixx="0.0" ixy="0.0" ixz="0.0" iyy="0.0" iyz="0.0" izz="0.0"/>
    </inertial>
    <visual>
      <material name="GreyB"/>
      <origin rpy="0 0 0 " xyz="0 0 0"/>
      <geometry name="neck_roll_geom">
        <mesh filename="package://meka_description/meshes/mid_res/S2R1/S2R1_SH2_neckRoll.dae"/>
      </geometry>
    </visual>
    <collision>
      <origin rpy="0.0 0.0 0.0 " xyz="0 0 0"/>
      <geometry name="S2R1_SH2_neckRoll_collision">
        <box size="0.01 0.01 0.01"/>
      </geometry>
    </collision>
  </link>
  <joint name="head_j2" type="revolute">
    <axis xyz="-1 0 0"/>
    <origin rpy="0 0 0" xyz="0 0 0"/>
    <parent link="neck_roll"/>
    <child link="neck_yaw"/>
    <limit effort="100" lower="-0.276983752292" upper="0.276983752292" velocity="0.872664625997"/>
  </joint>
  <link name="neck_yaw">
    <inertial>
      <mass value="0.496"/>
      <origin xyz="-0.010690 0.053982 0.000045"/>
      <inertia ixx="0.001094" ixy="0.000284" ixz="0.000000" iyy="0.000311" iyz="0.000000" izz="0.001222"/>
    </inertial>
    <visual>
      <material name="GreyC"/>
      <origin rpy="0 0 0 " xyz="0 0 0"/>
      <geometry name="S2R1_H3_neckYaw_geom">
        <mesh filename="package://meka_description/meshes/mid_res/S2R1/S2R1_H3_neckYaw.dae"/>
      </geometry>
    </visual>
    <collision>
      <origin rpy="0.0 0.0 0.0 " xyz="0 0 0"/>
      <geometry name="S2R1_H3_neckYaw_collision">
        <box size="0.01 0.01 0.01"/>
      </geometry>
    </collision>
  </link>
  <joint name="head_j3" type="revolute">
    <axis xyz="0 -1 0"/>
    <origin rpy="0 0 0" xyz="0 0 0"/>
    <parent link="neck_yaw"/>
    <child link="head_shell"/>
    <limit effort="100" lower="-0.13962634016" upper="-0.0349065850399" velocity="0.872664625997"/>
  </joint>
  <link name="head_shell">
    <inertial>
      <mass value="3.178"/>
      <origin xyz="0.034944 0.000563 0.058668"/>
      <inertia ixx="0.022924" ixy="-0.000034" ixz="-0.002929" iyy="0.021814" iyz="-0.000235" izz="0.026783"/>
    </inertial>
    <visual>
      <material name="GreyA"/>
      <origin rpy="0 0 0 " xyz="0 0 0"/>
      <geometry name="head_shell_geom">
        <mesh filename="package://meka_description/meshes/mid_res/S2R1/S2R1_H4_SIMC_head.dae"/>
        <!--<mesh filename="package://${MESH}/S2R1/S2R1_H4_UTA_head.dae" />-->
      </geometry>
    </visual>
    <collision>
      <origin rpy="0.0 0.0 0.0 " xyz="0 0 0"/>
      <geometry name="head_shell_collision">
        <mesh filename="package://meka_description/meshes/low_res/S2R1/S2R1_H4_SIMC_head.stl"/>
      </geometry>
    </collision>
  </link>
  <joint name="head_j4" type="revolute">
    <axis xyz="0 -1 0"/>
    <limit effort="100" lower="-1.22347580565" upper="1.22347580565" velocity="27.9252680319"/>
    <origin rpy="0 0 0" xyz="0.12508 0 0"/>
    <parent link="head_shell"/>
    <child link="eye_tilt"/>
  </joint>
  <link name="eye_tilt">
    <visual>
      <material name="GreyC"/>
      <origin rpy="0 0 0 " xyz="0 0 0"/>
      <geometry name="eye_tilt_geom">
        <mesh filename="package://meka_description/meshes/mid_res/S2R1/S2R1_SH5_eyeTilt.dae"/>
      </geometry>
    </visual>
    <collision>
      <origin rpy="0.0 0.0 0.0 " xyz="0 0 0"/>
      <geometry name="eye_tilt_collision">
        <box size="0.01 0.01 0.01"/>
      </geometry>
    </collision>
  </link>
  <joint name="head_j5" type="revolute">
    <axis xyz="0 0 1"/>
    <limit effort="100" lower="-0.654323936573" upper="0.652753140246" velocity="27.9252680319"/>
    <origin rpy="0 0 0" xyz="0 -0.053 0"/>
    <parent link="eye_tilt"/>
    <child link="right_eye"/>
  </joint>
  <link name="right_eye">
    <visual>
      <material name="GreyC"/>
      <origin rpy="0 0 0 " xyz="0 0 0"/>
      <geometry name="right_eye_geom">
        <mesh filename="package://meka_description/meshes/mid_res/S2R1/S2R1_eye.dae"/>
      </geometry>
    </visual>
    <collision>
      <origin rpy="0.0 0.0 0.0 " xyz="0 0 0"/>
      <geometry name="right_eye_collision">
        <mesh filename="package://meka_description/meshes/low_res/S2R1/S2R1_eye.stl"/>
      </geometry>
    </collision>
  </link>
  <joint name="head_j6" type="revolute">
    <axis xyz="0 0 1"/>
    <limit effort="100" lower="-0.661479786506" upper="0.663050582833" velocity="27.9252680319"/>
    <origin rpy="0 0 0" xyz="0 0.053 0"/>
    <parent link="eye_tilt"/>
    <child link="left_eye"/>
  </joint>
  <link name="left_eye">
    <visual>
      <material name="GreyC"/>
      <origin rpy="0 0 0 " xyz="0 0 0"/>
      <geometry name="left_eye_geom">
        <mesh filename="package://meka_description/meshes/mid_res/S2R1/S2R1_eye.dae"/>
      </geometry>
    </visual>
    <collision>
      <origin rpy="0.0 0.0 0.0 " xyz="0 0 0"/>
      <geometry name="left_eye_collision">
        <mesh filename="package://meka_description/meshes/low_res/S2R1/S2R1_eye.stl"/>
      </geometry>
    </collision>
  </link>
  <joint name="head_j7_rt_eyelid_top" type="revolute">
    <axis xyz="0 -1 0"/>
    <limit effort="100" lower="0.0349065850399" upper="1.18682389136" velocity="27.9252680319"/>
    <origin rpy="0 0.785 0" xyz="0 0.0 0"/>
    <parent link="right_eye"/>
    <child link="rt_eyelid_top"/>
  </joint>
  <link name="rt_eyelid_top">
    <visual>
      <material name="GreyC"/>
      <origin rpy="0 0 0 " xyz="0 0 0"/>
      <geometry name="rt_eyelid_top_geom">
        <mesh filename="package://meka_description/meshes/mid_res/S2R1/eyelid_top.dae"/>
      </geometry>
    </visual>
    <collision>
      <origin rpy="0.0 0.0 0.0 " xyz="0 0 0"/>
      <geometry name="rt_eyelid_top_collision">
        <box size="0.01 0.01 0.01"/>
      </geometry>
    </collision>
  </link>
  <joint name="head_j7_rt_eyelid_bottom" type="revolute">
    <axis xyz="0 1 0"/>
    <limit effort="100" lower="0.0349065850399" upper="1.18682389136" velocity="27.9252680319"/>
    <origin rpy="0 -0.785 0" xyz="0 0.0 0"/>
    <parent link="right_eye"/>
    <child link="rt_eyelid_bottom"/>
  </joint>
  <link name="rt_eyelid_bottom">
    <visual>
      <material name="GreyC"/>
      <origin rpy="0 0 0 " xyz="0 0 0"/>
      <geometry name="eyelid_bottom_geom">
        <mesh filename="package://meka_description/meshes/mid_res/S2R1/eyelid_bottom.dae"/>
      </geometry>
    </visual>
    <collision>
      <origin rpy="0.0 0.0 0.0 " xyz="0 0 0"/>
      <geometry name="eyelid_bottom_collision">
        <box size="0.01 0.01 0.01"/>
      </geometry>
    </collision>
  </link>
  <joint name="head_j7_lt_eyelid_top" type="revolute">
    <axis xyz="0 -1 0"/>
    <limit effort="100" lower="0.0349065850399" upper="1.18682389136" velocity="27.9252680319"/>
    <origin rpy="0 0.785 0" xyz="0 0.0 0"/>
    <parent link="left_eye"/>
    <child link="lt_eyelid_top"/>
  </joint>
  <link name="lt_eyelid_top">
    <visual>
      <material name="GreyC"/>
      <origin rpy="0 0 0 " xyz="0 0 0"/>
      <geometry name="lt_eyelid_top_geom">
        <mesh filename="package://meka_description/meshes/mid_res/S2R1/eyelid_top.dae"/>
      </geometry>
    </visual>
    <collision>
      <origin rpy="0.0 0.0 0.0 " xyz="0 0 0"/>
      <geometry name="lt_eyelid_top_collision">
        <box size="0.01 0.01 0.01"/>
      </geometry>
    </collision>
  </link>
  <joint name="head_j7_lt_eyelid_bottom" type="revolute">
    <axis xyz="0 1 0"/>
    <limit effort="100" lower="0.0349065850399" upper="1.18682389136" velocity="27.9252680319"/>
    <origin rpy="0 -0.785 0" xyz="0 0.0 0"/>
    <parent link="left_eye"/>
    <child link="lt_eyelid_bottom"/>
  </joint>
  <link name="lt_eyelid_bottom">
    <visual>
      <material name="GreyC"/>
      <origin rpy="0 0 0 " xyz="0 0 0"/>
      <geometry name="eyelid_bottom_geom2">
        <mesh filename="package://meka_description/meshes/mid_res/S2R1/eyelid_bottom.dae"/>
      </geometry>
    </visual>
    <collision>
      <origin rpy="0.0 0.0 0.0 " xyz="0 0 0"/>
      <geometry name="eyelid_bottom_collision2">
        <box size="0.01 0.01 0.01"/>
      </geometry>
    </collision>
  </link>
  <joint name="head_j8" type="revolute">
    <axis xyz="0 0 1"/>
    <limit effort="100" lower="-2.61799387799" upper="2.61799387799" velocity="27.9252680319"/>
    <origin rpy="-1.13 0 0" xyz="0.022 0.138 0.120"/>
    <parent link="head_shell"/>
    <child link="ear_roll"/>
  </joint>
  <link name="ear_roll">
    <visual>
      <material name="GreyC"/>
      <origin rpy="0 0 0 " xyz="0 0 0"/>
      <geometry name="ear_roll_geom">
        <mesh filename="package://meka_description/meshes/mid_res/S2R1/ear_mount.dae"/>
      </geometry>
    </visual>
    <collision>
      <origin rpy="0.0 0.0 0.0 " xyz="0 0 0"/>
      <geometry name="ear_roll_collision">
        <box size="0.01 0.01 0.01"/>
      </geometry>
    </collision>
  </link>
  <joint name="head_j9" type="revolute">
    <axis xyz="0 -1 0"/>
    <limit effort="100" lower="0.0" upper="2.14675497995" velocity="27.9252680319"/>
    <origin rpy="0 1.07 0" xyz="0.0 0.0 0.0"/>
    <parent link="ear_roll"/>
    <child link="ear1"/>
  </joint>
  <link name="ear1">
    <visual>
      <material name="GreyC"/>
      <origin rpy="0 0 0 " xyz="0 0 0"/>
      <geometry name="ear1_geom">
        <mesh filename="package://meka_description/meshes/mid_res/S2R1/ear.dae"/>
      </geometry>
    </visual>
    <collision>
      <origin rpy="0.0 0.0 0.0 " xyz="0 0 0"/>
      <geometry name="ear1_collision">
        <box size="0.01 0.01 0.01"/>
      </geometry>
    </collision>
  </link>
  <joint name="head_j10" type="revolute">
    <axis xyz="0 0 1"/>
    <limit effort="100" lower="-2.61799387799" upper="2.61799387799" velocity="27.9252680319"/>
    <origin rpy="1.13 0 0" xyz="0.022 -0.138 0.120"/>
    <parent link="head_shell"/>
    <child link="ear_roll2"/>
  </joint>
  <link name="ear_roll2">
    <visual>
      <material name="GreyC"/>
      <origin rpy="0 0 0 " xyz="0 0 0"/>
      <geometry name="ear_roll_geom2">
        <mesh filename="package://meka_description/meshes/mid_res/S2R1/ear_mount.dae"/>
      </geometry>
    </visual>
    <collision>
      <origin rpy="0.0 0.0 0.0 " xyz="0 0 0"/>
      <geometry name="ear_roll_collision2">
        <box size="0.01 0.01 0.01"/>
      </geometry>
    </collision>
  </link>
  <joint name="head_j11" type="revolute">
    <axis xyz="0 -1 0"/>
    <limit effort="100" lower="0.0" upper="2.14675497995" velocity="27.9252680319"/>
    <origin rpy="0 1.07 0" xyz="0.0 0.0 0.0"/>
    <parent link="ear_roll2"/>
    <child link="ear2"/>
  </joint>
  <link name="ear2">
    <visual>
      <material name="GreyC"/>
      <origin rpy="0 0 0 " xyz="0 0 0"/>
      <geometry name="ear2_geom">
        <mesh filename="package://meka_description/meshes/mid_res/S2R1/ear.dae"/>
      </geometry>
    </visual>
    <collision>
      <origin rpy="0.0 0.0 0.0 " xyz="0 0 0"/>
      <geometry name="ear2_collision">
        <box size="0.01 0.01 0.01"/>
      </geometry>
    </collision>
  </link>
  <joint name="right_arm_j0" type="revolute">
    <axis xyz="0 -1 0"/>
    <origin rpy="0 0 0" xyz="0.0 -0.18465 0.2337"/>
    <!-- transform from parent link to this joint frame -->
    <parent link="upper"/>
    <child link="shoulderupper_RIGHT"/>
    <limit effort="40" lower="-1.3962634016" upper="3.49065850399" velocity="0.523598775598"/>
    <dynamics damping="1.0"/>
  </joint>
  <link name="shoulderupper_RIGHT">
    <inertial>
      <mass value="2.0310"/>
      <origin xyz="-0.010946 0.025127 0.000022"/>
      <inertia ixx="0.003461" ixy="0.000428" ixz="0.000002" iyy="0.003097" iyz="0.000000" izz="0.005416"/>
    </inertial>
    <visual>
      <material name="GreyA"/>
      <origin rpy="0 0 0 " xyz="0 0 0"/>
      <geometry name="r_shoulder_geom">
        <mesh filename="package://meka_description/meshes/mid_res/A2R3/A2R3_RT1_shoulderRoll.dae"/>
      </geometry>
    </visual>
    <collision>
      <origin rpy="0.0 0.0 0.0 " xyz="0 0 0"/>
      <geometry name="r_shoulder_collision_geom">
        <mesh filename="package://meka_description/meshes/low_res/A2R3/A2R3_RT1_shoulderRoll.stl"/>
      </geometry>
    </collision>
  </link>
  <joint name="right_arm_j1" type="revolute">
    <axis xyz="-1 0 0"/>
    <limit effort="40" lower="-0.418879020479" upper="2.61799387799" velocity="0.523598775598"/>
    <origin rpy="0 0 0" xyz="0 0 0"/>
    <parent link="shoulderupper_RIGHT"/>
    <child link="shoulderpitch_RIGHT"/>
    <dynamics damping="1.0"/>
  </joint>
  <link name="shoulderpitch_RIGHT">
    <inertial>
      <mass value="0.566"/>
      <origin xyz="0.000944 -0.026331 -0.043257"/>
      <inertia ixx="0.000754" ixy="0.000015" ixz="0.000014" iyy="0.000921" iyz="0.000142" izz="0.000834"/>
    </inertial>
    <visual>
      <material name="GreyB"/>
      <origin rpy="0 0 0 " xyz="0 0 0"/>
      <geometry name="shoulderpitch_RIGHT">
        <mesh filename="package://meka_description/meshes/mid_res/A2R3/A2R3_RT2_shoulderPitch.dae"/>
      </geometry>
    </visual>
    <collision>
      <origin rpy="0.0 0.0 0.0 " xyz="0 0 0"/>
      <geometry name="shoulderpitch_RIGHT_collision">
        <mesh filename="package://meka_description/meshes/low_res/A2R3/A2R3_RT2_shoulderPitch.stl"/>
      </geometry>
    </collision>
  </link>
  <joint name="right_arm_j2" type="revolute">
    <axis xyz="0 0 -1"/>
    <origin rpy="0 0 0" xyz="0 -0.03175 -0.27857"/>
    <parent link="shoulderpitch_RIGHT"/>
    <child link="bicep_RIGHT"/>
    <limit effort="20" lower="-1.4835298642" upper="1.4835298642" velocity="0.872664625997"/>
    <dynamics damping="1.0"/>
  </joint>
  <link name="bicep_RIGHT">
    <inertial>
      <mass value="2.296"/>
      <origin xyz="-0.005767 0.084539 0.001385"/>
      <inertia ixx="0.013031" ixy="-0.000564" ixz="-0.000077" iyy="0.002070" iyz="0.000162" izz="0.013173"/>
    </inertial>
    <visual>
      <material name="GreyC"/>
      <origin rpy="0 0 0 " xyz="0 0 0"/>
      <geometry name="bicep_RIGHT_geom">
        <mesh filename="package://meka_description/meshes/mid_res/A2R3/A2R3_RT3_bicep.dae"/>
      </geometry>
    </visual>
    <collision>
      <origin rpy="0.0 0.0 0.0 " xyz="0 0 0"/>
      <geometry name="bicep_RIGHT_geom_collision">
        <mesh filename="package://meka_description/meshes/low_res/A2R3/A2R3_RT3_bicep.stl"/>
      </geometry>
    </collision>
  </link>
  <joint name="right_arm_j3" type="revolute">
    <axis xyz="0 -1 0"/>
    <origin rpy="0 0 0" xyz="0.00502 0  0"/>
    <parent link="bicep_RIGHT"/>
    <child link="elbowclevis_RIGHT"/>
    <limit effort="20" lower="-0.00486908464063" upper="2.31810267927" velocity="0.872664625997"/>
    <dynamics damping="10.0"/>
  </joint>
  <link name="elbowclevis_RIGHT">
    <inertial>
      <mass value="0.223"/>
      <origin xyz="-0.000002 0.000278 -0.026124"/>
      <inertia ixx="0.000470" ixy="0.000000" ixz="0.000000" iyy="0.000233" iyz="0.000019" izz="0.000425"/>
    </inertial>
    <visual>
      <material name="GreyA"/>
      <origin rpy="0 0 0 " xyz="0 0 0"/>
      <geometry name="elbowclevis_RIGHT_geom">
        <mesh filename="package://meka_description/meshes/mid_res/A2R3/A2R3_RT4_elbow.dae"/>
      </geometry>
    </visual>
    <collision>
      <origin rpy="0.0 0.0 0.0 " xyz="0 0 0"/>
      <geometry name="elbowclevis_RIGHT_collision">
        <mesh filename="package://meka_description/meshes/low_res/A2R3/A2R3_RT4_elbow.stl"/>
      </geometry>
    </collision>
  </link>
  <joint name="right_arm_j4" type="revolute">
    <axis xyz="0 0 -1"/>
    <limit effort="4" lower="-0.343829862643" upper="3.48542251623" velocity="2.61799387799"/>
    <origin rpy="0 0 0" xyz="0 0 -0.27747"/>
    <parent link="elbowclevis_RIGHT"/>
    <child link="wrist_RIGHT"/>
    <dynamics damping="1.0"/>
  </joint>
  <link name="wrist_RIGHT">
    <inertial>
      <mass value="1.468"/>
      <origin xyz="-0.004404 0.000124 0.130931"/>
      <inertia ixx="0.006099" ixy="0.000004" ixz="-0.000043" iyy="0.006120" iyz="0.000015" izz="0.001179"/>
    </inertial>
    <visual>
      <material name="GreyC"/>
      <origin rpy="0 0 0 " xyz="0 0 0"/>
      <geometry name="wrist_RIGHT_geom">
        <mesh filename="package://meka_description/meshes/mid_res/A2R3/A2R3_T5_forearmRoll.dae"/>
      </geometry>
    </visual>
    <collision>
      <origin rpy="0.0 0.0 0.0 " xyz="0 0 0"/>
      <geometry name="wrist_RIGHT_collision">
        <mesh filename="package://meka_description/meshes/low_res/A2R3/A2R3_T5_forearmRoll.stl"/>
      </geometry>
    </collision>
  </link>
  <joint name="right_arm_j5" type="revolute">
    <dynamics damping="1.0"/>
    <axis xyz="0 -1 0"/>
    <origin rpy="0 0 0" xyz="0 0 0"/>
    <parent link="wrist_RIGHT"/>
    <child link="w_differential_RIGHT"/>
    <limit effort="8" lower="-1.02677719895" upper="1.02677719895" velocity="0.698131700798"/>
    <dynamics damping="1.0"/>
  </joint>
  <link name="w_differential_RIGHT">
    <inertial>
      <mass value="0.278"/>
      <origin xyz="0 0 0"/>
      <inertia ixx="0" ixy="0" ixz="0" iyy="0" iyz="0" izz="0"/>
    </inertial>
    <visual>
      <material name="GreyB"/>
      <origin rpy="0 0 0 " xyz="0 0 0"/>
      <geometry name="w_differential_RIGHT_geom">
        <mesh filename="package://meka_description/meshes/mid_res/A2R3/A2R3_T6_wristDiff.dae"/>
      </geometry>
    </visual>
    <collision>
      <origin rpy="0.0 0.0 0.0 " xyz="0 0 0"/>
      <geometry name="w_differential_RIGHT_collision">
        <box size="0.01 0.01 0.01"/>
      </geometry>
    </collision>
  </link>
  <joint name="right_arm_j6" type="revolute">
    <axis xyz="-1 0 0"/>
    <limit effort="8" lower="-1.0471975512" upper="1.0471975512" velocity="0.698131700798"/>
    <origin rpy="0 0 0" xyz="0 0 0"/>
    <parent link="w_differential_RIGHT"/>
    <child link="handmount_RIGHT"/>
    <dynamics damping="1.0"/>
  </joint>
  <link name="handmount_RIGHT">
    <inertial>
      <mass value="0.093"/>
      <origin xyz="0 0 0"/>
      <inertia ixx="0" ixy="0" ixz="0" iyy="0" iyz="0" izz="0"/>
    </inertial>
    <visual>
      <material name="GreyA"/>
      <origin rpy="0 0 0 " xyz="0 0 0"/>
      <geometry name="handmount_RIGHT_geom">
        <mesh filename="package://meka_description/meshes/mid_res/A2R3/A2R3_T7_wristYaw.dae"/>
      </geometry>
    </visual>
    <collision>
      <origin rpy="0.0 0.0 0.0 " xyz="0 0 0"/>
      <geometry name="handmount_RIGHT_collision">
        <mesh filename="package://meka_description/meshes/low_res/A2R3/A2R3_T7_wristYaw.stl"/>
      </geometry>
    </collision>
  </link>
  <joint name="left_arm_j0" type="revolute">
    <axis xyz="0 -1 0"/>
    <origin rpy="0 0 0" xyz="0.0 0.18465 0.2337"/>
    <!-- transform from parent link to this joint frame -->
    <parent link="upper"/>
    <child link="shoulderupper_LEFT"/>
    <limit effort="40" lower="-1.3962634016" upper="3.49065850399" velocity="0.523598775598"/>
    <dynamics damping="10.0"/>
    <safety_controller k_position="100" k_velocity="10" soft_lower_limit="-0.564601836603" soft_upper_limit="2.1353981634"/>
    <!-- joint angle when the rising or the falling flag is activated on PR2 -->
  </joint>
  <link name="shoulderupper_LEFT">
    <inertial>
      <mass value="25.799322"/>
      <origin rpy="0 0 0" xyz="-0.001201 0.024513 -0.098231"/>
      <inertia ixx="0.866179142480" ixy="-0.06086507933" ixz="-0.12118061183" iyy="0.87421714893" iyz="-0.05886609911" izz="0.27353821674"/>
    </inertial>
    <visual>
      <material name="GreyA"/>
      <origin rpy="3.14 0 0 " xyz="0 0 0"/>
      <geometry name="l_shoulder_geom">
        <mesh filename="package://meka_description/meshes/mid_res/A2R3/A2R3_RT1_shoulderRoll.dae"/>
      </geometry>
    </visual>
    <collision>
      <origin rpy="3.14 0.0 0.0 " xyz="0 0 0"/>
      <geometry name="l_shoulder_collision_geom">
        <mesh filename="package://meka_description/meshes/low_res/A2R3/A2R3_RT1_shoulderRoll.stl"/>
      </geometry>
    </collision>
  </link>
  <joint name="left_arm_j1" type="revolute">
    <axis xyz="-1 0 0"/>
    <!-- Limits updated from Function's CAD values as of 2009_02_24 (link_data.xls) -->
    <limit effort="40" lower="-2.61799387799" upper="0.418879020479" velocity="0.523598775598"/>
    <safety_controller k_position="100" k_velocity="10" soft_lower_limit="-0.3536" soft_upper_limit="1.3463"/>
    <dynamics damping="10.0"/>
    <origin rpy="0 0 0" xyz="0 0 0"/>
    <parent link="shoulderupper_LEFT"/>
    <child link="shoulderpitch_LEFT"/>
  </joint>
  <link name="shoulderpitch_LEFT">
    <inertial>
      <mass value="2.74988"/>
      <origin rpy="0 0 0" xyz="0.02195 -0.02664 -0.03127"/>
      <inertia ixx="0.02105584615" ixy="0.00496704022" ixz="-0.00194808955" iyy="0.02127223737" iyz="0.00110425490" izz="0.01975753814"/>
    </inertial>
    <visual>
      <material name="GreyB"/>
      <origin rpy="0 0 3.14" xyz="0 0 0"/>
      <geometry name="l_shoulderpitch_RIGHT">
        <mesh filename="package://meka_description/meshes/mid_res/A2R3/A2R3_RT2_shoulderPitch.dae"/>
      </geometry>
    </visual>
    <collision>
      <origin rpy="0.0 0.0 3.14" xyz="0 0 0"/>
      <geometry name="l_shoulderpitch_RIGHT_collision">
        <mesh filename="package://meka_description/meshes/low_res/A2R3/A2R3_RT2_shoulderPitch.stl"/>
      </geometry>
    </collision>
  </link>
  <joint name="left_arm_j2" type="revolute">
    <axis xyz="0 0 -1"/>
    <origin rpy="0 0 0" xyz="0 0.03175 -0.27857"/>
    <parent link="shoulderpitch_LEFT"/>
    <child link="bicep_LEFT"/>
    <limit effort="20" lower="-1.4835298642" upper="1.4835298642" velocity="0.872664625997"/>
    <safety_controller k_position="100" k_velocity="2" soft_lower_limit="-0.65" soft_upper_limit="3.75"/>
    <dynamics damping="0.1"/>
  </joint>
  <link name="bicep_LEFT">
    <inertial>
      <!-- dummy mass, to be removed -->
      <mass value="0.1"/>
      <origin rpy="0 0 0" xyz="0.0 0 0"/>
      <inertia ixx="0.01" ixy="0.00" ixz="0.00" iyy="0.01" iyz="0.00" izz="0.01"/>
    </inertial>
    <visual>
      <material name="GreyC"/>
      <origin rpy="0 0 0 " xyz="0 0 0"/>
      <geometry name="bicep_LEFT_geom">
        <mesh filename="package://meka_description/meshes/mid_res/A2R3/A2R3_LT3_bicep.dae"/>
      </geometry>
    </visual>
    <collision>
      <origin rpy="0.0 0.0 0.0 " xyz="0 0 0"/>
      <geometry name="bicep_LEFT_geom_collision">
        <mesh filename="package://meka_description/meshes/low_res/A2R3/A2R3_LT3_bicep.stl"/>
      </geometry>
    </collision>
  </link>
  <joint name="left_arm_j3" type="revolute">
    <axis xyz="0 -1 0"/>
    <origin rpy="0 0 0" xyz="0.00502 0  0"/>
    <parent link="bicep_LEFT"/>
    <child link="elbowclevis_LEFT"/>
    <limit effort="20" lower="-0.00486908464063" upper="2.31810267927" velocity="0.872664625997"/>
  </joint>
  <link name="elbowclevis_LEFT">
    <inertial>
      <!-- NOTE:reflect==-1 for right side, reflect==1 for the left side -->
      <mass value="6.01769"/>
      <origin xyz="0.21405 0.01658 -0.00057"/>
      <inertia ixx="0.01530603856" ixy="-0.00339324862" ixz="0.00060765455" iyy="0.07473694455" iyz="-0.00019953729" izz="0.07601594191"/>
    </inertial>
    <visual>
      <material name="GreyA"/>
      <origin rpy="0 0 3.14 " xyz="0 0 0"/>
      <geometry name="elbowclevis_LEFT_geom">
        <mesh filename="package://meka_description/meshes/mid_res/A2R3/A2R3_RT4_elbow.dae"/>
      </geometry>
    </visual>
    <collision>
      <origin rpy="0.0 0.0 0.0 " xyz="0 0 0"/>
      <geometry name="elbowclevis_LEFT_collision">
        <mesh filename="package://meka_description/meshes/low_res/A2R3/A2R3_RT4_elbow.stl"/>
      </geometry>
    </collision>
  </link>
  <joint name="left_arm_j4" type="revolute">
    <axis xyz="0 0 -1"/>
    <limit effort="4" lower="-3.32834288355" upper="0.343829862643" velocity="2.61799387799"/>
    <safety_controller k_position="100" k_velocity="3" soft_lower_limit="-2.05" soft_upper_limit="0.0"/>
    <dynamics damping="1.0"/>
    <origin rpy="0 0 0" xyz="0 0 -0.27747"/>
    <parent link="elbowclevis_LEFT"/>
    <child link="wrist_LEFT"/>
  </joint>
  <link name="wrist_LEFT">
    <inertial>
      <mass value="1.90327"/>
      <origin xyz="0.01014 0.00032 -0.01211"/>
      <inertia ixx="0.00346541989" ixy="0.00004066825" ixz="0.00043171614" iyy="0.00441606455" iyz="-0.00003968914" izz="0.00359156824"/>
    </inertial>
    <visual>
      <material name="GreyC"/>
      <origin rpy="0 0 0 " xyz="0 0 0"/>
      <geometry name="wrist_LEFT_geom">
        <mesh filename="package://meka_description/meshes/mid_res/A2R3/A2R3_T5_forearmRoll.dae"/>
      </geometry>
    </visual>
    <collision>
      <origin rpy="0.0 0.0 0.0 " xyz="0 0 0"/>
      <geometry name="wrist_LEFT_collision">
        <mesh filename="package://meka_description/meshes/low_res/A2R3/A2R3_T5_forearmRoll.stl"/>
      </geometry>
    </collision>
  </link>
  <joint name="left_arm_j5" type="revolute">
    <axis xyz="0 -1 0"/>
    <origin rpy="0 0 0" xyz="0 0 0"/>
    <parent link="wrist_LEFT"/>
    <child link="w_differential_LEFT"/>
    <limit effort="8" lower="-1.02677719895" upper="1.02677719895" velocity="0.698131700798"/>
  </joint>
  <link name="w_differential_LEFT">
    <inertial>
      <mass value="2.57968"/>
      <origin xyz="0.18791 -0.00017 -0.00912"/>
      <inertia ixx="0.00364857222" ixy="0.00005215877" ixz="0.00071534842" iyy="0.01507736897" iyz="-0.00001310770" izz="0.01659310749"/>
    </inertial>
    <visual>
      <material name="GreyB"/>
      <origin rpy="0 0 0 " xyz="0 0 0"/>
      <geometry name="w_differential_LEFT_geom">
        <mesh filename="package://meka_description/meshes/mid_res/A2R3/A2R3_T6_wristDiff.dae"/>
      </geometry>
    </visual>
    <collision>
      <origin rpy="0.0 0.0 0.0 " xyz="0 0 0"/>
      <geometry name="w_differential_LEFT_collision">
        <box size="0.01 0.01 0.01"/>
      </geometry>
    </collision>
  </link>
  <joint name="left_arm_j6" type="revolute">
    <axis xyz="-1 0 0"/>
    <limit effort="8" lower="-1.0471975512" upper="1.0471975512" velocity="0.698131700798"/>
    <safety_controller k_position="20" k_velocity="4" soft_lower_limit="0.1" soft_upper_limit="2.0"/>
    <dynamics damping="0.1"/>
    <origin rpy="0 0 0" xyz="0 0 0"/>
    <parent link="w_differential_LEFT"/>
    <child link="handmount_LEFT"/>
  </joint>
  <link name="handmount_LEFT">
    <inertial>
      <mass value="0.61402"/>
      <origin xyz="-0.00157 0.0 -0.00075"/>
      <inertia ixx="0.00065165722" ixy="0.00000028864" ixz="0.00000303477" iyy="0.00019824443" iyz="-0.00000022645" izz="0.00064450498"/>
    </inertial>
    <visual>
      <material name="GreyA"/>
      <origin rpy="0 0 0 " xyz="0 0 0"/>
      <geometry name="handmount_LEFT_geom">
        <mesh filename="package://meka_description/meshes/mid_res/A2R3/A2R3_T7_wristYaw.dae"/>
      </geometry>
    </visual>
    <collision>
      <origin rpy="0.0 0.0 0.0 " xyz="0 0 0"/>
      <geometry name="handmount_LEFT_collision">
        <mesh filename="package://meka_description/meshes/low_res/A2R3/A2R3_T7_wristYaw.stl"/>
      </geometry>
    </collision>
  </link>
  <link name="world"/>
  <link name="base_link"/>
  <!-- Solid Base -->
  <joint name="base_joint" type="fixed">
    <origin rpy="0 0 0" xyz="0 0 1"/>
    <parent link="world"/>
    <child link="base_link"/>
  </joint>
  <joint name="X" type="prismatic">
    <axis xyz="1 0 0"/>
    <origin rpy="0 0 0" xyz="0.0 0.0 0.0"/>
    <parent link="base_link"/>
    <child link="dummy_1"/>
    <limit effort="30" lower="-0.714601836603" upper="2.2853981634" velocity="3.48"/>
    <dynamics damping="10.0"/>
    <safety_controller k_position="100" k_velocity="10" soft_lower_limit="-0.564601836603" soft_upper_limit="2.1353981634"/>
  </joint>
  <link name="dummy_1">
    <inertial>
      <mass value="25.799322"/>
      <origin rpy="0 0 0" xyz="0.0 0.0 0.0"/>
      <inertia ixx="0.866179142480" ixy="-0.06086507933" ixz="-0.12118061183" iyy="0.87421714893" iyz="-0.05886609911" izz="0.27353821674"/>
    </inertial>
    <visual>
      <material name="GreyA"/>
      <origin rpy="0 0 0 " xyz="0 0 0"/>
      <geometry name="b1r1_1_geom">
        <box size="0.01 0.01 0.01"/>
      </geometry>
    </visual>
    <collision>
      <origin rpy="0.0 0.0 0.0 " xyz="0 0 0"/>
      <geometry name="b1r1_1_collision_geom">
        <box size="0.01 0.01 0.01"/>
      </geometry>
    </collision>
  </link>
  <joint name="Y" type="prismatic">
    <axis xyz="0 1 0"/>
    <limit effort="30" lower="-0.5236" upper="1.3963" velocity="3.47"/>
    <safety_controller k_position="100" k_velocity="10" soft_lower_limit="-0.3536" soft_upper_limit="1.3463"/>
    <dynamics damping="10.0"/>
    <origin rpy="0 0 0" xyz="0 0 0"/>
    <parent link="dummy_1"/>
    <child link="dummy_2"/>
  </joint>
  <link name="dummy_2">
    <inertial>
      <mass value="2.74988"/>
      <origin rpy="0 0 0" xyz="0.0 0.0 0.0"/>
      <inertia ixx="0.02105584615" ixy="0.00496704022" ixz="-0.00194808955" iyy="0.02127223737" iyz="0.00110425490" izz="0.01975753814"/>
    </inertial>
    <visual>
      <material name="GreyB"/>
      <origin rpy="0 0 0 " xyz="0 0 0"/>
      <geometry name="b1r1_2_geom">
        <box size="0.01 0.01 0.01"/>
      </geometry>
    </visual>
    <collision>
      <origin rpy="0.0 0.0 0.0 " xyz="0 0 0"/>
      <geometry name="b1r1_2_collision_geom">
        <box size="0.01 0.01 0.01"/>
      </geometry>
    </collision>
  </link>
  <joint name="yaw" type="revolute">
    <axis xyz="0 0 1"/>
    <origin rpy="0 0 0" xyz="0 0.0 0.0"/>
    <parent link="dummy_2"/>
    <child link="dummy_3"/>
    <limit effort="30" lower="-0.8" upper="3.9" velocity="5.45"/>
    <safety_controller k_position="100" k_velocity="2" soft_lower_limit="-0.65" soft_upper_limit="3.75"/>
    <dynamics damping="0.1"/>
  </joint>
  <link name="dummy_3">
    <inertial>
      <mass value="1000"/>
      <origin xyz="0 0 0"/>
      <inertia ixx="1000" ixy="0" ixz="0" iyy="1000" iyz="0" izz="1000"/>
    </inertial>
    <visual>
      <material name="GreyC"/>
      <origin rpy="0 0 0" xyz="0 0 0"/>
      <geometry name="b1r1_3_geom">
        <mesh filename="package://meka_description/meshes/mid_res/B1R1/MB1_00_000_meka_mobile_base+backpack+zlift.dae"/>
      </geometry>
    </visual>
    <collision>
      <origin rpy="0.0 0.0 0.0 " xyz="0 0 0"/>
      <geometry name="b1r1_3_geom">
        <mesh filename="package://meka_description/meshes/low_res/B1R1/MB1_00_000_meka_mobile_base+backpack+zlift.stl"/>
      </geometry>
    </collision>
  </link>
  <joint name="zlift_joint" type="prismatic">
    <axis xyz="0 0 1"/>
    <origin rpy="0 0 0" xyz="0.43 0.0 0.75"/>
    <!-- transform from parent link to this joint frame -->
    <parent link="dummy_3"/>
    <child link="zlift_link"/>
    <limit effort="30" lower="0.0" upper="557.8944954" velocity="3.48"/>
    <dynamics damping="10.0"/>
    <safety_controller k_position="100" k_velocity="10" soft_lower_limit="-0.564601836603" soft_upper_limit="2.1353981634"/>
  </joint>
  <link name="zlift_link">
    <inertial>
      <mass value="25.799322"/>
      <origin rpy="0 0 0" xyz="0.0 0.0 0.0"/>
      <inertia ixx="0.866179142480" ixy="-0.06086507933" ixz="-0.12118061183" iyy="0.87421714893" iyz="-0.05886609911" izz="0.27353821674"/>
    </inertial>
    <visual>
      <material name="GreyA"/>
      <origin rpy="0 0 0 " xyz="0 0 0"/>
      <geometry name="z_lift_geom">
        <mesh filename="package://meka_description/meshes/mid_res/B1R1/MB1_00_011_festo-chest_mount_assy+spacer.dae"/>
      </geometry>
    </visual>
    <collision>
      <origin rpy="0.0 0.0 0.0 " xyz="0 0 0"/>
      <geometry name="z_lift_geom_collision_geom">
        <mesh filename="package://meka_description/meshes/low_res/B1R1/MB1_00_011_festo-chest_mount_assy+spacer.stl"/>
      </geometry>
    </collision>
  </link>
  <!-- Solid Base -->
  <joint name="chest_joint" type="fixed">
    <origin rpy="0 0 0" xyz="0 0 -0.03"/>
    <parent link="zlift_link"/>
    <child link="upper"/>
  </joint>
  <link name="upper">
    <inertial>
      <mass value="1000"/>
      <origin xyz="0 0 0"/>
      <inertia ixx="1000" ixy="0" ixz="0" iyy="1000" iyz="0" izz="1000"/>
    </inertial>
    <visual>
      <material name="GreyC"/>
      <origin rpy="0 0 0" xyz="0 0 0"/>
      <geometry name="upper_geom">
        <mesh filename="package://meka_description/meshes/mid_res/A2R3/A2R3_T4_Chest_Neck.dae"/>
      </geometry>
      <material name="Blue"/>
    </visual>
    <collision>
      <origin rpy="0.0 0.0 0.0 " xyz="0 0 0"/>
      <geometry name="upper_collision_geom">
        <mesh filename="package://meka_description/meshes/low_res/A2R3/A2R3_T4_Chest_Neck.stl"/>
      </geometry>
    </collision>
  </link>
</robot>

